{"uuid": "a5f7fcd8-6e60-42c9-8e0b-8562e0d3ae68", "children": ["a2bd595f-c2d4-4d47-8c0e-d271b87be060", "ebd2d4a1-dff4-4a22-a345-cea9a28b2b6b", "94a2ea38-769a-4edb-bd7f-e27f065aa47e", "11c3f113-63ef-4d02-ab7f-a1e9f08dfed2", "cb940b69-12f7-4309-9681-6586324e3ead", "d39d7175-cf8c-4980-8748-e190be9d7180", "5d6146bb-2b95-409a-8cf9-2c6ad7db3318"], "befores": [{"name": "f4", "status": "broken", "statusDetails": {"message": "requests.exceptions.ConnectionError: HTTPConnectionPool(host='www.joysurvey.com', port=8089): Max retries exceeded with url: /survey/man/user/login (Caused by NewConnectionError('<urllib3.connection.HTTPConnection object at 0x00000160809521F0>: Failed to establish a new connection: [WinError 10060] 由于连接方在一段时间后没有正确答复或连接的主机没有反应，连接尝试失败。'))\n", "trace": "  File \"c:\\users\\zhouj\\appdata\\local\\programs\\python\\python38\\lib\\site-packages\\pluggy\\_callers.py\", line 39, in _multicall\n    res = hook_impl.function(*args)\n  File \"c:\\users\\zhouj\\appdata\\local\\programs\\python\\python38\\lib\\site-packages\\_pytest\\fixtures.py\", line 1111, in pytest_fixture_setup\n    result = call_fixture_func(fixturefunc, request, kwargs)\n  File \"c:\\users\\zhouj\\appdata\\local\\programs\\python\\python38\\lib\\site-packages\\_pytest\\fixtures.py\", line 883, in call_fixture_func\n    fixture_result = next(generator)\n  File \"E:\\KT03\\jiekou\\conftest.py\", line 88, in test_login_success\n    res = req.visit('post', login_url, data=payload)\n  File \"E:\\KT03\\jiekou\\common\\requests_handler.py\", line 15, in visit\n    result = self.session.request(method, url, params=params, data=data, json=json, headers=headers)\n  File \"c:\\users\\zhouj\\appdata\\local\\programs\\python\\python38\\lib\\site-packages\\requests\\sessions.py\", line 587, in request\n    resp = self.send(prep, **send_kwargs)\n  File \"c:\\users\\zhouj\\appdata\\local\\programs\\python\\python38\\lib\\site-packages\\requests\\sessions.py\", line 701, in send\n    r = adapter.send(request, **kwargs)\n  File \"c:\\users\\zhouj\\appdata\\local\\programs\\python\\python38\\lib\\site-packages\\requests\\adapters.py\", line 565, in send\n    raise ConnectionError(e, request=request)\n"}, "start": 1664359001023, "stop": 1664359043129}], "start": 1664359001023, "stop": 1664359044581}